<sdf version='1.11'>
  <model name='robot'>
    <link name='base_link'>
      <inertial>
        <pose>0.094117647058823528 0 0.20000000000000001 0 0 0</pose>
        <mass>4.25</mass>
        <inertia>
          <ixx>0.087916666666666643</ixx>
          <ixy>0</ixy>
          <ixz>0.0049999999999999914</ixz>
          <iyy>0.090074295343137212</iyy>
          <iyz>0</iyz>
          <izz>0.087574295343137279</izz>
        </inertia>
      </inertial>
      <collision name='base_link_fixed_joint_lump__box_link_collision'>
        <pose>0.10000000000000001 0 0.14999999999999999 0 0 0</pose>
        <geometry>
          <box>
            <size>0.40000000000000002 0.40000000000000002 0.20000000000000001</size>
          </box>
        </geometry>
      </collision>
      <collision name='base_link_fixed_joint_lump__cylinder_link_collision_1'>
        <pose>0.10000000000000001 0 0.29999999999999999 0 0 0</pose>
        <geometry>
          <cylinder>
            <length>0.29999999999999999</length>
            <radius>0.10000000000000001</radius>
          </cylinder>
        </geometry>
      </collision>
      <collision name='base_link_fixed_joint_lump__camera_link_collision_2'>
        <pose>0 0 0.40000000000000002 0 0 0</pose>
        <geometry>
          <box>
            <size>0.025000000000000001 0.10000000000000001 0.10000000000000001</size>
          </box>
        </geometry>
        <surface>
          <contact>
            <ode/>
          </contact>
          <friction>
            <ode/>
          </friction>
        </surface>
      </collision>
      <visual name='base_link_fixed_joint_lump__box_link_visual'>
        <pose>0.10000000000000001 0 0.14999999999999999 0 0 0</pose>
        <geometry>
          <box>
            <size>0.40000000000000002 0.40000000000000002 0.20000000000000001</size>
          </box>
        </geometry>
        <material>
          <diffuse>1 1 1 1</diffuse>
          <ambient>1 1 1 1</ambient>
        </material>
      </visual>
      <visual name='base_link_fixed_joint_lump__cylinder_link_visual_1'>
        <pose>0.10000000000000001 0 0.29999999999999999 0 0 0</pose>
        <geometry>
          <cylinder>
            <length>0.29999999999999999</length>
            <radius>0.10000000000000001</radius>
          </cylinder>
        </geometry>
        <material>
          <diffuse>1 0.125 0.125 1</diffuse>
          <ambient>1 0.125 0.125 1</ambient>
        </material>
      </visual>
      <visual name='base_link_fixed_joint_lump__camera_link_visual_2'>
        <pose>0 0 0.40000000000000002 0 0 0</pose>
        <geometry>
          <box>
            <size>0.025000000000000001 0.10000000000000001 0.10000000000000001</size>
          </box>
        </geometry>
        <material>
          <diffuse>0 1 1 1</diffuse>
          <ambient>0 1 1 1</ambient>
        </material>
      </visual>
      <sensor name='thermal_camera_8bit' type='thermal'>
        <camera>
          <horizontal_fov>1.0469999999999999</horizontal_fov>
          <image>
            <width>320</width>
            <height>240</height>
            <format>L8</format>
          </image>
          <clip>
            <near>0.10000000000000001</near>
            <far>100</far>
          </clip>
        </camera>
        <always_on>true</always_on>
        <update_rate>30</update_rate>
        <visualize>true</visualize>
        <topic>thermal_camera_8bit/image</topic>
        <plugin name='gz::sim::systems::ThermalSensor' filename='gz-sim-thermal-sensor-system'>
          <min_temp>253.15</min_temp>
          <max_temp>673.15</max_temp>
          <resolution>3.0</resolution>
        </plugin>
        <pose>0.10000000000000001 0 0.40000000000000002 0 0 0</pose>
      </sensor>
    </link>
    <joint name='back_left_wheel_joint' type='revolute'>
      <pose relative_to='base_link'>0.20000000000000001 0.22 0.050000000000000003 -1.5707963267948959 0 0</pose>
      <parent>base_link</parent>
      <child>back_left_wheel_link</child>
      <axis>
        <xyz>0 0 -1</xyz>
        <limit>
          <lower>-inf</lower>
          <upper>inf</upper>
        </limit>
        <dynamics>
          <spring_reference>0</spring_reference>
          <spring_stiffness>0</spring_stiffness>
        </dynamics>
      </axis>
    </joint>
    <link name='back_left_wheel_link'>
      <pose relative_to='back_left_wheel_joint'>0 0 0 0 0 0</pose>
      <inertial>
        <pose>0 0 0 0 0 0</pose>
        <mass>0.10000000000000001</mass>
        <inertia>
          <ixx>7.5833333333333352e-05</ixx>
          <ixy>0</ixy>
          <ixz>0</ixz>
          <iyy>7.5833333333333352e-05</iyy>
          <iyz>0</iyz>
          <izz>0.000125</izz>
        </inertia>
      </inertial>
      <collision name='back_left_wheel_link_collision'>
        <pose>0 0 0 0 0 0</pose>
        <geometry>
          <cylinder>
            <length>0.040000000000000001</length>
            <radius>0.050000000000000003</radius>
          </cylinder>
        </geometry>
      </collision>
      <visual name='back_left_wheel_link_visual'>
        <pose>0 0 0 0 0 0</pose>
        <geometry>
          <cylinder>
            <length>0.040000000000000001</length>
            <radius>0.050000000000000003</radius>
          </cylinder>
        </geometry>
        <material>
          <diffuse>1 1 0 1</diffuse>
          <ambient>1 1 0 1</ambient>
        </material>
      </visual>
    </link>
    <joint name='back_right_wheel_joint' type='revolute'>
      <pose relative_to='base_link'>0.20000000000000001 -0.22 0.050000000000000003 -1.5707963267948959 0 0</pose>
      <parent>base_link</parent>
      <child>back_right_wheel_link</child>
      <axis>
        <xyz>0 0 -1</xyz>
        <limit>
          <lower>-inf</lower>
          <upper>inf</upper>
        </limit>
        <dynamics>
          <spring_reference>0</spring_reference>
          <spring_stiffness>0</spring_stiffness>
        </dynamics>
      </axis>
    </joint>
    <link name='back_right_wheel_link'>
      <pose relative_to='back_right_wheel_joint'>0 0 0 0 0 0</pose>
      <inertial>
        <pose>0 0 0 0 0 0</pose>
        <mass>0.10000000000000001</mass>
        <inertia>
          <ixx>7.5833333333333352e-05</ixx>
          <ixy>0</ixy>
          <ixz>0</ixz>
          <iyy>7.5833333333333352e-05</iyy>
          <iyz>0</iyz>
          <izz>0.000125</izz>
        </inertia>
      </inertial>
      <collision name='back_right_wheel_link_collision'>
        <pose>0 0 0 0 0 0</pose>
        <geometry>
          <cylinder>
            <length>0.040000000000000001</length>
            <radius>0.050000000000000003</radius>
          </cylinder>
        </geometry>
      </collision>
      <visual name='back_right_wheel_link_visual'>
        <pose>0 0 0 0 0 0</pose>
        <geometry>
          <cylinder>
            <length>0.040000000000000001</length>
            <radius>0.050000000000000003</radius>
          </cylinder>
        </geometry>
        <material>
          <diffuse>1 1 0 1</diffuse>
          <ambient>1 1 0 1</ambient>
        </material>
      </visual>
    </link>
    <joint name='front_left_wheel_joint' type='revolute'>
      <pose relative_to='base_link'>0 0.22 0.050000000000000003 -1.5707963267948959 0 0</pose>
      <parent>base_link</parent>
      <child>front_left_wheel_link</child>
      <axis>
        <xyz>0 0 -1</xyz>
        <limit>
          <lower>-inf</lower>
          <upper>inf</upper>
        </limit>
        <dynamics>
          <spring_reference>0</spring_reference>
          <spring_stiffness>0</spring_stiffness>
        </dynamics>
      </axis>
    </joint>
    <link name='front_left_wheel_link'>
      <pose relative_to='front_left_wheel_joint'>0 0 0 0 0 0</pose>
      <inertial>
        <pose>0 0 0 0 0 0</pose>
        <mass>0.10000000000000001</mass>
        <inertia>
          <ixx>7.5833333333333352e-05</ixx>
          <ixy>0</ixy>
          <ixz>0</ixz>
          <iyy>7.5833333333333352e-05</iyy>
          <iyz>0</iyz>
          <izz>0.000125</izz>
        </inertia>
      </inertial>
      <collision name='front_left_wheel_link_collision'>
        <pose>0 0 0 0 0 0</pose>
        <geometry>
          <cylinder>
            <length>0.040000000000000001</length>
            <radius>0.050000000000000003</radius>
          </cylinder>
        </geometry>
      </collision>
      <visual name='front_left_wheel_link_visual'>
        <pose>0 0 0 0 0 0</pose>
        <geometry>
          <cylinder>
            <length>0.040000000000000001</length>
            <radius>0.050000000000000003</radius>
          </cylinder>
        </geometry>
        <material>
          <diffuse>1 1 0 1</diffuse>
          <ambient>1 1 0 1</ambient>
        </material>
      </visual>
    </link>
    <joint name='front_right_wheel_joint' type='revolute'>
      <pose relative_to='base_link'>0 -0.22 0.050000000000000003 -1.5707963267948959 0 0</pose>
      <parent>base_link</parent>
      <child>front_right_wheel_link</child>
      <axis>
        <xyz>0 0 -1</xyz>
        <limit>
          <lower>-inf</lower>
          <upper>inf</upper>
        </limit>
        <dynamics>
          <spring_reference>0</spring_reference>
          <spring_stiffness>0</spring_stiffness>
        </dynamics>
      </axis>
    </joint>
    <link name='front_right_wheel_link'>
      <pose relative_to='front_right_wheel_joint'>0 0 0 0 0 0</pose>
      <inertial>
        <pose>0 0 0 0 0 0</pose>
        <mass>0.10000000000000001</mass>
        <inertia>
          <ixx>7.5833333333333352e-05</ixx>
          <ixy>0</ixy>
          <ixz>0</ixz>
          <iyy>7.5833333333333352e-05</iyy>
          <iyz>0</iyz>
          <izz>0.000125</izz>
        </inertia>
      </inertial>
      <collision name='front_right_wheel_link_collision'>
        <pose>0 0 0 0 0 0</pose>
        <geometry>
          <cylinder>
            <length>0.040000000000000001</length>
            <radius>0.050000000000000003</radius>
          </cylinder>
        </geometry>
      </collision>
      <visual name='front_right_wheel_link_visual'>
        <pose>0 0 0 0 0 0</pose>
        <geometry>
          <cylinder>
            <length>0.040000000000000001</length>
            <radius>0.050000000000000003</radius>
          </cylinder>
        </geometry>
        <material>
          <diffuse>1 1 0 1</diffuse>
          <ambient>1 1 0 1</ambient>
        </material>
      </visual>
    </link>
    <plugin name='gz::sim::systems::DiffDrive' filename='gz-sim-diff-drive-system'>
      <left_joint>front_left_wheel_joint</left_joint>
      <right_joint>front_right_wheel_joint</right_joint>
      <wheel_separation>0.4</wheel_separation>
      <wheel_radius>0.05</wheel_radius>
      <odom_publish_frequency>1</odom_publish_frequency>
      <topic>cmd_vel</topic>
    </plugin>
    <plugin name='gz::sim::systems::TriggeredPublisher' filename='gz-sim-triggered-publisher-system'>
      <input topic='/keyboard/keypress' type='gz.msgs.Int32'>
        <match field='data'>16777235</match>
      </input>
      <output topic='/cmd_vel' type='gz.msgs.Twist'>linear: {x: 1.0}, angular: {z: 0.0}</output>
    </plugin>
    <plugin name='gz::sim::systems::TriggeredPublisher' filename='gz-sim-triggered-publisher-system'>
      <input topic='/keyboard/keypress' type='gz.msgs.Int32'>
        <match field='data'>16777236</match>
      </input>
      <output topic='/cmd_vel' type='gz.msgs.Twist'>linear: {x: 0.0}, angular: {z: 3.0}</output>
    </plugin>
    <plugin name='gz::sim::systems::TriggeredPublisher' filename='gz-sim-triggered-publisher-system'>
      <input topic='/keyboard/keypress' type='gz.msgs.Int32'>
        <match field='data'>16777237</match>
      </input>
      <output topic='/cmd_vel' type='gz.msgs.Twist'>linear: {x: -1.0}, angular: {z: 0.0}</output>
    </plugin>
    <plugin name='gz::sim::systems::TriggeredPublisher' filename='gz-sim-triggered-publisher-system'>
      <input topic='/keyboard/keypress' type='gz.msgs.Int32'>
        <match field='data'>16777234</match>
      </input>
      <output topic='/cmd_vel' type='gz.msgs.Twist'>linear: {x: 0.0}, angular: {z: -3.0}</output>
    </plugin>
    <frame name='box_joint' attached_to='base_link'>
      <pose>0 0 0.050000000000000003 0 0 0</pose>
    </frame>
    <frame name='box_link' attached_to='box_joint'>
      <pose>0 0 0 0 0 0</pose>
    </frame>
    <frame name='camera_joint' attached_to='cylinder_link'>
      <pose>0 0 0.10000000000000001 0 0 0</pose>
    </frame>
    <frame name='camera_link' attached_to='camera_joint'>
      <pose>0 0 0 0 0 0</pose>
    </frame>
    <frame name='cylinder_joint' attached_to='base_link'>
      <pose>0.10000000000000001 0 0.29999999999999999 0 0 0</pose>
    </frame>
    <frame name='cylinder_link' attached_to='cylinder_joint'>
      <pose>0 0 0 0 0 0</pose>
    </frame>
  </model>
</sdf>
