<?xml version="1.0" ?>
<!-- =================================================================================== -->
<!-- |    This document was autogenerated by xacro from robot.urdf.xacro               | -->
<!-- |    EDITING THIS FILE BY HAND IS NOT RECOMMENDED                                 | -->
<!-- =================================================================================== -->
<robot name="robot">
  <!-- Inertial tensor of cuboid and cylinder -->
  <!-- WORLD LINK [origin reference of frame] -->
  <link name="base_link"> 
    
    </link>
  <!-- BOX [box parts of the robot body] -->
  <joint name="box_joint" type="fixed">
    <parent link="base_link"/>
    <child link="box_link"/>
    <origin xyz="0 0 0.05"/>
  </joint>
  <link name="box_link">
    <visual>
      <origin xyz="0.1 0 0.1"/>
      <geometry>
        <box size="0.4 0.4 0.2"/>
      </geometry>
      <material name="green">
        <color rgba="0.1 1 0.1 1"/>
      </material>
    </visual>
    <collision>
      <origin xyz="0.1 0 0.1"/>
      <geometry>
        <box size="0.4 0.4 0.2"/>
      </geometry>
    </collision>
    <inertial>
      <origin rpy="0 0 0" xyz="0.1 0 0.1"/>
      <mass value="3"/>
      <inertia ixx="0.05000000000000001" ixy="0.0" ixz="0.0" iyy="0.05000000000000001" iyz="0.0" izz="0.08000000000000002"/>
    </inertial>
  </link>
  <!-- cylinder [cylinder parts of the robot body] -->
  <joint name="cylinder_joint" type="fixed">
    <parent link="base_link"/>
    <child link="cylinder_link"/>
    <origin rpy="0 0 0" xyz="0.1 0 0.3"/>
    <axis xyz="0 0 -1"/>
  </joint>
  <link name="cylinder_link">
    <visual>
      <origin xyz="0 0 0"/>
      <geometry>
        <cylinder length="0.3" radius="0.1"/>
      </geometry>
      <material name="red">
        <color rgba="1 0.1 0.1 1"/>
      </material>
    </visual>
    <collision>
      <origin xyz="0 0 0"/>
      <geometry>
        <cylinder length="0.3" radius="0.1"/>
      </geometry>
    </collision>
    <inertial>
      <origin rpy="0 0 0" xyz="0 0 0"/>
      <mass value="1"/>
      <inertia ixx="0.009999999999999998" ixy="0.0" ixz="0.0" iyy="0.009999999999999998" iyz="0.0" izz="0.005000000000000001"/>
    </inertial>
  </link>
  <!-- camera [camera of robot] -->
  <joint name="camera_joint" type="fixed">
    <parent link="cylinder_link"/>
    <child link="camera_link"/>
    <origin xyz="0 0 0.1"/>
  </joint>
  <link name="camera_link">
    <visual>
      <origin xyz="-0.1 0 0"/>
      <geometry>
        <box size="0.025 0.1 0.1"/>
      </geometry>
      <material name="cyan">
        <color rgba="0 1 1 1"/>
      </material>
    </visual>
    <collision>
      <origin xyz="-0.1 0 0"/>
      <geometry>
        <box size="0.025 0.1 0.1"/>
      </geometry>
    </collision>
    <inertial>
      <origin rpy="0 0 0" xyz="-0.1 0 0"/>
      <mass value="0.25"/>
      <inertia ixx="0.00041666666666666675" ixy="0.0" ixz="0.0" iyy="0.0002213541666666667" iyz="0.0" izz="0.0002213541666666667"/>
    </inertial>
  </link>
  <gazebo>
    <plugin filename="ignition-gazebo-sensors-system" name="ignition::gazebo::systems::Sensors">
      <render_engine>ogre2</render_engine>
    </plugin>
  </gazebo>
  <!-- 16 bit Thermal camera using -->
  <gazebo reference="camera_link">
    <sensor name="thermal_camera_16bit" type="thermal">
      <camera>
        <horizontal_fov>1.98968</horizontal_fov>
        <image>
          <width>320</width>
          <height>240</height>
          <format>L16</format>
        </image>
        <clip>
          <near>0.1</near>
          <far>100</far>
        </clip>
      </camera>
      <always_on>1</always_on>
      <update_rate>30</update_rate>
      <visualize>true</visualize>
      <pose>0 0 0.5 0 0 3.141</pose>
      <topic>thermal_camera</topic>
      <plugin filename="ignition-gazebo-thermal-sensor-system" name="ignition::gazebo::systems::ThermalSensor">
        <min_temp>250</min_temp>
        <max_temp>1000</max_temp>
      </plugin>
    </sensor>
  </gazebo>
  <!-- back left wheel [wheel of robot] -->
  <joint name="back_left_wheel_joint" type="continuous">
    <parent link="base_link"/>
    <child link="back_left_wheel_link"/>
    <origin rpy="-1.5707963267948966 0 0" xyz="0.20 0.22 0.05"/>
    <axis xyz="0 0 -1"/>
  </joint>
  <link name="back_left_wheel_link">
    <visual>
      <geometry>
        <cylinder length="0.04" radius="0.05"/>
      </geometry>
      <material name="yellow">
        <color rgba="1 1 0 1"/>
      </material>
    </visual>
    <collision>
      <geometry>
        <cylinder length="0.04" radius="0.05"/>
      </geometry>
    </collision>
    <inertial>
      <origin rpy="0 0 0" xyz="0 0 0"/>
      <mass value="0.1"/>
      <inertia ixx="7.583333333333335e-05" ixy="0.0" ixz="0.0" iyy="7.583333333333335e-05" iyz="0.0" izz="0.00012500000000000003"/>
    </inertial>
  </link>
  <!-- back right wheel [wheel of robot] -->
  <joint name="back_right_wheel_joint" type="continuous">
    <parent link="base_link"/>
    <child link="back_right_wheel_link"/>
    <origin rpy="-1.5707963267948966 0 0" xyz="0.20 -0.22 0.05"/>
    <axis xyz="0 0 -1"/>
  </joint>
  <link name="back_right_wheel_link">
    <visual>
      <geometry>
        <cylinder length="0.04" radius="0.05"/>
      </geometry>
      <material name="yellow">
        <color rgba="1 1 0 1"/>
      </material>
    </visual>
    <collision>
      <geometry>
        <cylinder length="0.04" radius="0.05"/>
      </geometry>
    </collision>
    <inertial>
      <origin rpy="0 0 0" xyz="0 0 0"/>
      <mass value="0.1"/>
      <inertia ixx="7.583333333333335e-05" ixy="0.0" ixz="0.0" iyy="7.583333333333335e-05" iyz="0.0" izz="0.00012500000000000003"/>
    </inertial>
  </link>
  <!-- front left wheel [wheel of robot] -->
  <joint name="front_left_wheel_joint" type="continuous">
    <parent link="base_link"/>
    <child link="front_left_wheel_link"/>
    <origin rpy="-1.5707963267948966 0 0" xyz="0 0.22 0.05"/>
    <axis xyz="0 0 -1"/>
  </joint>
  <link name="front_left_wheel_link">
    <visual>
      <geometry>
        <cylinder length="0.04" radius="0.05"/>
      </geometry>
      <material name="yellow">
        <color rgba="1 1 0 1"/>
      </material>
    </visual>
    <collision>
      <geometry>
        <cylinder length="0.04" radius="0.05"/>
      </geometry>
    </collision>
    <inertial>
      <origin rpy="0 0 0" xyz="0 0 0"/>
      <mass value="0.1"/>
      <inertia ixx="7.583333333333335e-05" ixy="0.0" ixz="0.0" iyy="7.583333333333335e-05" iyz="0.0" izz="0.00012500000000000003"/>
    </inertial>
  </link>
  <!-- front right wheel [wheel of robot] -->
  <joint name="front_right_wheel_joint" type="continuous">
    <parent link="base_link"/>
    <child link="front_right_wheel_link"/>
    <origin rpy="-1.5707963267948966 0 0" xyz="0 -0.22 0.05"/>
    <axis xyz="0 0 -1"/>
  </joint>
  <link name="front_right_wheel_link">
    <visual>
      <geometry>
        <cylinder length="0.04" radius="0.05"/>
      </geometry>
      <material name="yellow">
        <color rgba="1 1 0 1"/>
      </material>
    </visual>
    <collision>
      <geometry>
        <cylinder length="0.04" radius="0.05"/>
      </geometry>
    </collision>
    <inertial>
      <origin rpy="0 0 0" xyz="0 0 0"/>
      <mass value="0.1"/>
      <inertia ixx="7.583333333333335e-05" ixy="0.0" ixz="0.0" iyy="7.583333333333335e-05" iyz="0.0" izz="0.00012500000000000003"/>
    </inertial>
  </link>
  <!-- Plugin for differential drive and twist control-->
  <gazebo>
    <plugin filename="gz-sim-diff-drive-system" name="gz::sim::systems::DiffDrive">
      <left_joint>front_left_wheel_joint</left_joint>
      <right_joint>front_right_wheel_joint</right_joint>
      <wheel_separation>0.4</wheel_separation>
      <wheel_radius>0.05</wheel_radius>
      <odom_publish_frequency>1</odom_publish_frequency>
      <topic>cmd_vel</topic>
    </plugin>
    <plugin filename="gz-sim-triggered-publisher-system" name="gz::sim::systems::TriggeredPublisher">
      <input topic="/keyboard/keypress" type="gz.msgs.Int32">
        <match field="data">16777235</match>
      </input>
      <output topic="/cmd_vel" type="gz.msgs.Twist">
                linear: {x: 1.0}, angular: {z: 0.0}
            </output>
    </plugin>
    <plugin filename="gz-sim-triggered-publisher-system" name="gz::sim::systems::TriggeredPublisher">
      <input topic="/keyboard/keypress" type="gz.msgs.Int32">
        <match field="data">16777236</match>
      </input>
      <output topic="/cmd_vel" type="gz.msgs.Twist">
                linear: {x: 0.0}, angular: {z: 2.0}
            </output>
    </plugin>
    <plugin filename="gz-sim-triggered-publisher-system" name="gz::sim::systems::TriggeredPublisher">
      <input topic="/keyboard/keypress" type="gz.msgs.Int32">
        <match field="data">16777237</match>
      </input>
      <output topic="/cmd_vel" type="gz.msgs.Twist">
                linear: {x: -0.5}, angular: {z: 0.0}
            </output>
    </plugin>
    <plugin filename="gz-sim-triggered-publisher-system" name="gz::sim::systems::TriggeredPublisher">
      <input topic="/keyboard/keypress" type="gz.msgs.Int32">
        <match field="data">16777234</match>
      </input>
      <output topic="/cmd_vel" type="gz.msgs.Twist">
                linear: {x: 0.0}, angular: {z: -2.0}
            </output>
    </plugin>
  </gazebo>
</robot>
