<?xml version="1.0"?>

<robot xmlns:xacro="http://www.ros.org/wiki/xacro">
    <!-- back left wheel [wheel of robot] -->
    <joint name="back_left_wheel_joint" type="continuous">
        <parent link="base_link"/>
        <child link="back_left_wheel_link"/>
        <origin xyz="0.20 0.22 0.05" rpy="${-pi/2} 0 0"/>
        <axis xyz="0 0 -1"/>
    </joint>

    <link name="back_left_wheel_link">
        <visual>
            <geometry>
                <cylinder radius="0.05" length="0.04"/>
            </geometry>
            <material name="yellow">
                <color rgba="1 1 0 1"/>
            </material>
        </visual>
        <collision>
            <geometry>
                <cylinder radius="0.05" length="0.04"/>
            </geometry>
        </collision>
        <xacro:inertial_cylinder mass="0.1" length="0.04" radius="0.05">
            <origin xyz="0 0 0" rpy="0 0 0"/>
        </xacro:inertial_cylinder>
    </link>

    <!-- back right wheel [wheel of robot] -->
    <joint name="back_right_wheel_joint" type="continuous">
        <parent link="base_link"/>
        <child link="back_right_wheel_link"/>
        <origin xyz="0.20 -0.22 0.05" rpy="${-pi/2} 0 0"/>
        <axis xyz="0 0 -1"/>
    </joint>

    <link name="back_right_wheel_link">
        <visual>
            <geometry>
                <cylinder radius="0.05" length="0.04"/>
            </geometry>
            <material name="yellow">
                <color rgba="1 1 0 1"/>
            </material>
        </visual>
        <collision>
            <geometry>
                <cylinder radius="0.05" length="0.04"/>
            </geometry>
        </collision>
        <xacro:inertial_cylinder mass="0.1" length="0.04" radius="0.05">
            <origin xyz="0 0 0" rpy="0 0 0"/>
        </xacro:inertial_cylinder>
    </link>

    <!-- front left wheel [wheel of robot] -->
    <joint name="front_left_wheel_joint" type="continuous">
        <parent link="base_link"/>
        <child link="front_left_wheel_link"/>
        <origin xyz="0 0.22 0.05" rpy="${-pi/2} 0 0"/>
        <axis xyz="0 0 -1"/>
    </joint>

    <link name="front_left_wheel_link">
        <visual>
            <geometry>
                <cylinder radius="0.05" length="0.04"/>
            </geometry>
            <material name="yellow">
                <color rgba="1 1 0 1"/>
            </material>
        </visual>
        <collision>
            <geometry>
                <cylinder radius="0.05" length="0.04"/>
            </geometry>
        </collision>
        <xacro:inertial_cylinder mass="0.1" length="0.04" radius="0.05">
            <origin xyz="0 0 0" rpy="0 0 0"/>
        </xacro:inertial_cylinder>
    </link>

    <!-- front right wheel [wheel of robot] -->
    <joint name="front_right_wheel_joint" type="continuous">
        <parent link="base_link"/>
        <child link="front_right_wheel_link"/>
        <origin xyz="0 -0.22 0.05" rpy="${-pi/2} 0 0"/>
        <axis xyz="0 0 -1"/>
    </joint>

    <link name="front_right_wheel_link">
        <visual>
            <geometry>
                <cylinder radius="0.05" length="0.04"/>
            </geometry>
            <material name="yellow">
                <color rgba="1 1 0 1"/>
            </material>
        </visual>
        <collision>
            <geometry>
                <cylinder radius="0.05" length="0.04"/>
            </geometry>
        </collision>
        <xacro:inertial_cylinder mass="0.1" length="0.04" radius="0.05">
            <origin xyz="0 0 0" rpy="0 0 0"/>
        </xacro:inertial_cylinder>
    </link>

    <!-- Plugin for differential drive and twist control-->

    <gazebo>
        <plugin filename="gz-sim-diff-drive-system" name="gz::sim::systems::DiffDrive">
            <left_joint>front_left_wheel_joint</left_joint>
            <right_joint>front_right_wheel_joint</right_joint>
            <wheel_separation>0.4</wheel_separation>
            <wheel_radius>0.05</wheel_radius>
            <odom_publish_frequency>1</odom_publish_frequency>
            <topic>cmd_vel</topic>
        </plugin>

        <plugin filename="gz-sim-triggered-publisher-system" name="gz::sim::systems::TriggeredPublisher">
            <input type="gz.msgs.Int32" topic="/keyboard/keypress">
                <match field="data">16777235</match>
            </input>
            <output type="gz.msgs.Twist" topic="/cmd_vel">
                linear: {x: 1.0}, angular: {z: 0.0}
            </output>
        </plugin>

        <plugin filename="gz-sim-triggered-publisher-system" name="gz::sim::systems::TriggeredPublisher">
            <input type="gz.msgs.Int32" topic="/keyboard/keypress">
                <match field="data">16777236</match>
            </input>
            <output type="gz.msgs.Twist" topic="/cmd_vel">
                linear: {x:0.0}, angular: {z:2.0}
            </output>
        </plugin>

        <plugin filename="gz-sim-triggered-publisher-system" name="gz::sim::systems::TriggeredPublisher">
            <input type="gz.msgs.Int32" topic="/keyboard/keypress">
                <match field="data">16777237</match>
            </input>
            <output type="gz.msgs.Twist" topic="/cmd_vel">
                linear: {x: -0.5}, angular: {z: 0.0}
            </output>
        </plugin>

        <plugin filename="gz-sim-triggered-publisher-system" name="gz::sim::systems::TriggeredPublisher">
            <input type="gz.msgs.Int32" topic="/keyboard/keypress">
                <match field="data">16777234</match>
            </input>
            <output type="gz.msgs.Twist" topic="/cmd_vel">
                linear: {x: 0.0}, angular: {z: -2.0}
            </output>
        </plugin>
    </gazebo>

</robot>